Workbook

Sheet ReadMe
B2: Your Role | C2: Order Manager
B3: Today Date | C3: 45026 | D3: 2024 WK 15
B4: Task
B5: 1. Review Open Orders for WK16
B6: 2. Identify the available stocks and allocated supply to each customers
B7: 3. Identify and Classify If any bulk orders present with appropriate logic using historical orders
B8: 3. Provide Confirmation for WK16 Regular Orders
B9: 4. Provide the estimated supply date for Bulk Order
B10: 5. Calculate the additional production and cost required to meet the bulk orders
B11: 6. What is the final order confirmation status (Order quantity and Confirmed Date for each Order)
B12: 7. Summarise the final financial Implications after final order confirmation
B14: Data You have
B15: Historical Orders
B16: Current Open Orders
... B24: Penalty

Sheet Current Open Orders
A1: order_id | B1: product | C1: product_desc | D1: location | E1: required_date | F1: quantity | G1: customer_code | H1: customer_desc | I1: year | J1: week_no
A2: OD1899 | B2: Z22215 | C2: GenZPhone | D2: DC_central | E2: 45033 | F2: 11300 | G2: CC24 | H2: Pixel | I2: =YEAR(E2) -> 2023 | J2: =_xlfn.ISOWEEKNUM(E2) -> 16
A3: OD2982 | B3: Z22215 | C3: GenZPhone | D3: DC_central | E3: 45037 | F3: 4700 | G3: CC25 | H3: Astro | I3: =YEAR(E3) -> 2023 | J3: =_xlfn.ISOWEEKNUM(E3) -> 16
A4: OD3971 | B4: Z22215 | C4: GenZPhone | D4: DC_central | E4: 45037 | F4: 6121 | G4: CC26 | H4: Flipsell | I4: =YEAR(E4) -> 2023 | J4: =_xlfn.ISOWEEKNUM(E4) -> 16
A5: OD4873 | B5: Z22215 | C5: GenZPhone | D5: DC_central | E5: 45037 | F5: 1490 | G5: CC27 | H5: Tosco | I5: =YEAR(E5) -> 2023 | J5: =_xlfn.ISOWEEKNUM(E5) -> 16

Sheet Historical Orders
A1: order_id | B1: product | C1: product_desc | D1: location | E1: required_date | F1: quantity | G1: customer_code | H1: customer_desc | I1: year | J1: week_no
A2: OD1002 | B2: Z22215 | C2: GenZPhone | D2: DC_central | E2: 44340 | F2: 3190 | G2: CC24 | H2: Pixel | I2: =YEAR(E2) -> 2021 | J2: =_xlfn.ISOWEEKNUM(E2) -> 21
A3: OD1012 | B3: Z22215 | C3: GenZPhone | D3: DC_central | E3: 44347 | F3: 2920 | G3: CC24 | H3: Pixel | I3: =YEAR(E3) -> 2021 | J3: =_xlfn.ISOWEEKNUM(E3) -> 22
A4: OD1025 | B4: Z22215 | C4: GenZPhone | D4: DC_central | E4: 44354 | F4: 3270 | G4: CC24 | H4: Pixel | I4: =YEAR(E4) -> 2021 | J4: =_xlfn.ISOWEEKNUM(E4) -> 23
A5: OD1027 | B5: Z22215 | C5: GenZPhone | D5: DC_central | E5: 44361 | F5: 3180 | G5: CC24 | H5: Pixel | I5: =YEAR(E5) -> 2021 | J5: =_xlfn.ISOWEEKNUM(E5) -> 24
A6: OD1035 | B6: Z22215 | C6: GenZPhone | D6: DC_central | E6: 44368 | F6: 3020 | G6: CC24 | H6: Pixel | I6: =YEAR(E6) -> 2021 | J6: =_xlfn.ISOWEEKNUM(E6) -> 25
A7: OD1041 | B7: Z22215 | C7: GenZPhone | D7: DC_central | E7: 44375 | F7: 3290 | G7: CC24 | H7: Pixel | I7: =YEAR(E7) -> 2021 | J7: =_xlfn.ISOWEEKNUM(E7) -> 26
A8: OD1068 | B8: Z22215 | C8: GenZPhone | D8: DC_central | E8: 44382 | F8: 3000 | G8: CC24 | H8: Pixel | I8: =YEAR(E8) -> 2021 | J8: =_xlfn.ISOWEEKNUM(E8) -> 27
A9: OD1076 | B9: Z22215 | C9: GenZPhone | D9: DC_central | E9: 44389 | F9: 3110 | G9: CC24 | H9: Pixel | I9: =YEAR(E9) -> 2021 | J9: =_xlfn.ISOWEEKNUM(E9) -> 28
A10: OD1076 | B10: Z22215 | C10: GenZPhone | D10: DC_central | E10: 44396 | F10: 2810 | G10: CC24 | H10: Pixel | I10: =YEAR(E10) -> 2021 | J10: =_xlfn.ISOWEEKNUM(E10) -> 29
A11: OD1081 | B11: Z22215 | C11: GenZPhone | D11: DC_central | E11: 44403 | F11: 2940 | G11: CC24 | H11: Pixel | I11: =YEAR(E11) -> 2021 | J11: =_xlfn.ISOWEEKNUM(E11) -> 30
A12: OD1091 | B12: Z22215 | C12: GenZPhone | D12: DC_central | E12: 44410 | F12: 3110 | G12: CC24 | H12: Pixel | I12: =YEAR(E12) -> 2021 | J12: =_xlfn.ISOWEEKNUM(E12) -> 31
A13: OD1093 | B13: Z22215 | C13: GenZPhone | D13: DC_central | E13: 44417 | F13: 3230 | G13: CC24 | H13: Pixel | I13: =YEAR(E13) -> 2021 | J13: =_xlfn.ISOWEEKNUM(E13) -> 32
... A391: OD4872 | B391: Z22215 | C391: GenZPhone | D391: DC_central | E391: 45030 | F391: 1460 | G391: CC27 | H391: Tosco | I391: =YEAR(E391) -> 2023 | J391: =_xlfn.ISOWEEKNUM(E391) -> 15

Sheet FG_Projected_supply
A1: material | B1: material_desc | C1: location | D1: type | E1: 45033 | F1: =E1+7 -> 45040 | G1: =F1+7 -> 45047 | H1: =G1+7 -> 45054 | I1: =H1+7 -> 45061 | J1: =I1+7 -> 45068 | K1: =J1+7 -> 45075 | L1: =K1+7 -> 45082 | M1: =L1+7 -> 45089 | ... V1: =U1+7 -> 45152
A2: Z22215 | B2: GenZPhone | C2: DC_park | D2: on_hand | E2: 375
A3: Z22215 | B3: GenZPhone | C3: DC_park | D3: scheduled_receipt | E3: 15000 | F3: 15000 | G3: 15000 | H3: 15000 | I3: 15000 | J3: 15000 | K3: 15000 | L3: 15000 | M3: 15000 | N3: 15000 | O3: 15000 | P3: 15000 | Q3: 15000 | R3: 15000 | S3: 15000 | T3: 15000 | U3: 15000 | V3: 15000
A4: Z22215 | B4: GenZPhone | C4: DC_park | D4: total_Fgsupply (Opening Inventory) | E4: =SUM(E2+E3) -> 15375 | F4: =SUM(F2+F3) -> 15000 | G4: =SUM(G2+G3) -> 15000 | H4: =SUM(H2+H3) -> 15000 | I4: =SUM(I2+I3) -> 15000 | J4: =SUM(J2+J3) -> 15000 | K4: =SUM(K2+K3) -> 15000 | L4: =SUM(L2+L3) -> 15000 | ... V4: =SUM(V2+V3) -> 15000

Sheet FG_allocation
A1: material | B1: material_desc | C1: location | D1: customer_code | E1: customer_desc | F1: =G1-7 -> 45026 | G1: 45033 | H1: =G1+7 -> 45040 | I1: =H1+7 -> 45047 | J1: =I1+7 -> 45054 | K1: =J1+7 -> 45061 | L1: =K1+7 -> 45068 | M1: =L1+7 -> 45075 | N1: =M1+7 -> 45082 | O1: =N1+7 -> 45089 | ... X1: =W1+7 -> 45152
A2: Z22215 | B2: GenZPhone | C2: DC_park | D2: CC24 | E2: Pixel | F2: 0.22 | G2: 0.22 | H2: 0.22 | I2: 0.22 | J2: 0.22 | K2: 0.22 | L2: 0.22 | M2: 0.22 | N2: 0.22 | O2: 0.22 | P2: 0.22 | Q2: 0.22 | R2: 0.22 | S2: 0.22 | T2: 0.22 | U2: 0.22 | V2: 0.22 | W2: 0.22 | X2: 0.22
A3: Z22215 | B3: GenZPhone | C3: DC_park | D3: CC25 | E3: Astro | F3: 0.28 | G3: 0.28 | H3: 0.28 | I3: 0.28 | J3: 0.28 | K3: 0.28 | L3: 0.28 | M3: 0.28 | N3: 0.28 | O3: 0.28 | P3: 0.28 | Q3: 0.28 | R3: 0.28 | S3: 0.28 | T3: 0.28 | U3: 0.28 | V3: 0.28 | W3: 0.28 | X3: 0.28
A4: Z22215 | B4: GenZPhone | C4: DC_park | D4: CC26 | E4: Flipsell | F4: 0.4 | G4: 0.4 | H4: 0.4 | I4: 0.4 | J4: 0.4 | K4: 0.4 | L4: 0.4 | M4: 0.4 | N4: 0.4 | O4: 0.4 | P4: 0.4 | Q4: 0.4 | R4: 0.4 | S4: 0.4 | T4: 0.4 | U4: 0.4 | V4: 0.4 | W4: 0.4 | X4: 0.4
A5: Z22215 | B5: GenZPhone | C5: DC_park | D5: CC27 | E5: Tosco | F5: 0.1 | G5: 0.1 | H5: 0.1 | I5: 0.1 | J5: 0.1 | K5: 0.1 | L5: 0.1 | M5: 0.1 | N5: 0.1 | O5: 0.1 | P5: 0.1 | Q5: 0.1 | R5: 0.1 | S5: 0.1 | T5: 0.1 | U5: 0.1 | V5: 0.1 | W5: 0.1 | X5: 0.1

Sheet Daily Production Schedule
A1: material | B1: material_desc | C1: 45026 | D1: 45027 | E1: 45028 | F1: 45029 | G1: 45030 | H1: 45031 | I1: 45032 | J1: 45033 | K1: 45034 | L1: 45035 | M1: 45036 | N1: 45037 | O1: 45038 | P1: 45039 | Q1: 45040 | R1: 45041 | S1: 45042 | T1: 45043 | U1: 45044 | V1: 45045 | W1: 45046
A2: Z22215 | B2: GenZPhone | C2: 3000 | D2: 3000 | E2: 3000 | F2: 3000 | G2: 3000 | J2: 3000 | K2: 3000 | L2: 3000 | M2: 3000 | N2: 3000 | Q2: 3000 | R2: 3000 | S2: 3000 | T2: 3000 | U2: 3000

Sheet production_parameters
A1: item | B1: value | C1: uom
A2: Frozen_period | B2: Current + 3 | C2: days
A3: working days | B3: 5 | C3: days/week
A4: Z22215_module_linecapacity | B4: 3000 | C4: EA/shift
A5: Z22215_assembly_linecapacity | B5: 1000 | C5: EA/shift
A6: total_module_line | B6: 1 | C6: line
A7: total_assembly_line | B7: 3 | C7: line
A8: current_operational_shifts | B8: 1 | C8: shift/day
A9: working_daysperweek | B9: 5 | C9: days
A10: Total operational_cost_pershift | B10: =SUM(B11:B14) -> 685000 | C10: INR
A11: electricity | B11: 50000 | C11: INR
A12: transportation | B12: 125000 | C12: INR
A13: food | B13: 30000 | C13: INR
A14: shift_allowance(only for evening/night) | B14: 480000 | C14: INR

Sheet BOM
A1: Level | B1: Item | C1: material | D1: material_desc | E1: required_quantity | F1: uom | G1: source_type | H1: supplier_leadtime
A2: 0 | C2: Z22215 | D2: GenZPhone | E2: - | F2: - | G2: - | H2: -
A3: 1 | B3: 0010 | C3: CMP12800 | D3: engine_module | E3: 1 | F3: EA | G3: - | H3: -
A4: 1 | B4: 0020 | C4: CMP15169 | D4: back_cover | E4: 1 | F4: EA | G4: park | H4: 1
A5: 1 | B5: 0030 | C5: CMP12391 | D5: battery | E5: 1 | F5: EA | G5: import | H5: 7
A6: 1 | B6: 0040 | C6: CMP19654 | D6: user guide | E6: 1 | F6: EA | G6: local | H6: 2
A7: 1 | B7: 0050 | C7: CMP13058 | D7: charger | E7: 1 | F7: EA | G7: park | H7: 1
A8: 1 | B8: 0060 | C8: CMP13929 | D8: deliverybox | E8: 1 | F8: EA | G8: local | H8: 2
A9: 1 | C9: CMP12800 | D9: engine_module | E9: - | F9: - | G9: - | H9: -
A10: 2 | B10: 0010 | C10: CMP21187 | D10: flash_memory | E10: 1 | F10: EA | G10: import | H10: 10
A11: 2 | B11: 0020 | C11: CMP26771 | D11: display_panel | E11: 1 | F11: EA | G11: import | H11: 10
A12: 2 | B12: 0030 | C12: CMP23821 | D12: processor | E12: 1 | F12: EA | G12: import | H12: 7
A13: 2 | B13: 0040 | C13: CMP28635 | D13: camera_module | E13: 1 | F13: EA | G13: local | H13: 3
A14: 2 | B14: 0050 | C14: CMP15391 | D14: PCB | E14: 1 | F14: EA | G14: import | H14: 7
A15: 2 | B15: 0060 | C15: CMP17473 | D15: power_amplifier | E15: 1 | F15: EA | G15: local | H15: 3
A16: 2 | B16: 0070 | C16: CMP12619 | D16: sensor | E16: 1 | F16: EA | G16: local | H16: 2
A17: 2 | B17: 0080 | C17: CMP25013 | D17: speaker | E17: 1 | F17: EA | G17: local | H17: 2
A18: 2 | B18: 0090 | C18: CMP27957 | D18: mircophone | E18: 1 | F18: EA | G18: local | H18: 3
A19: 2 | B19: 0100 | C19: CMP19997 | D19: RAM | E19: 1 | F19: EA | G19: local | H19: 2

Sheet RM_projected_supply
A1: material | B1: material_desc | C1: 45029 | D1: 45030 | E1: 45031 | F1: 45032 | G1: 45033 | H1: 45034 | I1: 45035 | J1: 45036 | K1: 45037 | L1: 45038 | M1: 45039 | N1: 45040 | O1: 45041 | P1: 45042 | Q1: 45043 | R1: 45044 | S1: 45045 | T1: 45046
A2: CMP15169 | B2: back_cover | C2: 3630 | D2: 3000 | E2: 0 | F2: 0 | G2: 3000 | H2: 3000 | I2: 3000 | J2: 3000 | K2: 3000 | L2: 0 | M2: 0 | N2: 3000 | O2: 3000 | P2: 3000 | Q2: 3000 | R2: 3000 | S2: 0 | T2: 0
A3: CMP12391 | B3: battery | C3: 23410 | D3: 0 | E3: 0 | F3: 0 | G3: 0 | H3: 0 | I3: 0 | J3: 0 | K3: 0 | L3: 0 | M3: 0 | N3: 21000 | O3: 0 | P3: 0 | Q3: 0 | R3: 0 | S3: 0 | T3: 0
A4: CMP19654 | B4: user guide | C4: 7260 | D4: 0 | E4: 0 | F4: 0 | G4: 6000 | H4: 0 | I4: 6000 | J4: 0 | K4: 6000 | L4: 0 | M4: 0 | N4: 0 | O4: 6000 | P4: 0 | Q4: 6000 | R4: 0 | S4: 0 | T4: 0
A5: CMP13058 | B5: charger | C5: 3940 | D5: 3000 | E5: 0 | F5: 0 | G5: 3000 | H5: 3000 | I5: 3000 | J5: 3000 | K5: 3000 | L5: 0 | M5: 0 | N5: 3000 | O5: 3000 | P5: 3000 | Q5: 3000 | R5: 3000 | S5: 0 | T5: 0
A6: CMP13929 | B6: deliverybox | C6: 7260 | D6: 0 | E6: 0 | F6: 0 | G6: 6000 | H6: 0 | I6: 6000 | J6: 0 | K6: 6000 | L6: 0 | M6: 0 | N6: 0 | O6: 6000 | P6: 0 | Q6: 6000 | R6: 0 | S6: 0 | T6: 0
A7: CMP21187 | B7: flash_memory | C7: 37250 | D7: 0 | E7: 0 | F7: 0 | G7: 0 | H7: 0 | I7: 0 | J7: 0 | K7: 0 | L7: 0 | M7: 0 | N7: 0 | O7: 0 | P7: 0 | Q7: 30000 | R7: 0 | S7: 0 | T7: 0
A8: CMP26771 | B8: display_panel | C8: 36300 | D8: 0 | E8: 0 | F8: 0 | G8: 0 | H8: 0 | I8: 0 | J8: 0 | K8: 0 | L8: 0 | M8: 0 | N8: 0 | O8: 0 | P8: 0 | Q8: 30000 | R8: 0 | S8: 0 | T8: 0
A9: CMP23821 | B9: processor | C9: 24450 | D9: 0 | E9: 0 | F9: 0 | G9: 0 | H9: 0 | I9: 0 | J9: 0 | K9: 0 | L9: 0 | M9: 0 | N9: 21000 | O9: 0 | P9: 0 | Q9: 0 | R9: 0 | S9: 0 | T9: 0
A10: CMP28635 | B10: camera_module | C10: 11210 | D10: 0 | E10: 0 | F10: 0 | G10: 0 | H10: 9000 | I10: 0 | J10: 0 | K10: 9000 | L10: 0 | M10: 0 | N10: 0 | O10: 0 | P10: 9000 | Q10: 0 | R10: 0 | S10: 0 | T10: 0
A11: CMP15391 | B11: PCB | C11: 22410 | D11: 0 | E11: 0 | F11: 0 | G11: 0 | H11: 0 | I11: 0 | J11: 0 | K11: 0 | L11: 0 | M11: 0 | N11: 21000 | O11: 0 | P11: 0 | Q11: 0 | R11: 0 | S11: 0 | T11: 0
A12: CMP17473 | B12: power_amplifier | C12: 11000 | D12: 0 | E12: 0 | F12: 0 | G12: 0 | H12: 9000 | I12: 0 | J12: 0 | K12: 9000 | L12: 0 | M12: 0 | N12: 0 | O12: 0 | P12: 9000 | Q12: 0 | R12: 0 | S12: 0 | T12: 0
... A16: CMP19997 | B16: RAM | C16: 7300 | D16: 0 | E16: 0 | F16: 0 | G16: 6000 | H16: 0 | I16: 6000 | J16: 0 | K16: 6000 | L16: 0 | M16: 0 | N16: 0 | O16: 6000 | P16: 0 | Q16: 6000 | R16: 0 | S16: 0 | T16: 0
V38: EXPRESS LT

Sheet sourcing_parameters
A1: material | B1: material_desc | C1: source_type | D1: lead_time_normal | E1: lead_time_express | F1: lead_time
A2: CMP15169 | B2: back_cover | C2: park | D2: 1 | F2: =IF(E2="", D2, MIN(D2:E2)) -> 1
A3: CMP12391 | B3: battery | C3: import | D3: 7 | E3: 3 | F3: =IF(E3="", D3, MIN(D3:E3)) -> 3
A4: CMP19654 | B4: user guide | C4: local | D4: 2 | F4: =IF(E4="", D4, MIN(D4:E4)) -> 2
A5: CMP13058 | B5: charger | C5: park | D5: 1 | F5: =IF(E5="", D5, MIN(D5:E5)) -> 1
A6: CMP13929 | B6: deliverybox | C6: local | D6: 2 | F6: =IF(E6="", D6, MIN(D6:E6)) -> 2
A7: CMP21187 | B7: flash_memory | C7: import | D7: 10 | E7: 3 | F7: =IF(E7="", D7, MIN(D7:E7)) -> 3
A8: CMP26771 | B8: display_panel | C8: import | D8: 10 | E8: 3 | F8: =IF(E8="", D8, MIN(D8:E8)) -> 3
A9: CMP23821 | B9: processor | C9: import | D9: 7 | E9: 3 | F9: =IF(E9="", D9, MIN(D9:E9)) -> 3
A10: CMP28635 | B10: camera_module | C10: local | D10: 3 | F10: =IF(E10="", D10, MIN(D10:E10)) -> 3
A11: CMP15391 | B11: PCB | C11: import | D11: 7 | E11: 3 | F11: =IF(E11="", D11, MIN(D11:E11)) -> 3
A12: CMP17473 | B12: power_amplifier | C12: local | D12: 3 | E12: 1 | F12: =IF(E12="", D12, MIN(D12:E12)) -> 1
A13: CMP12619 | B13: sensor | C13: local | D13: 2 | F13: =IF(E13="", D13, MIN(D13:E13)) -> 2
A14: CMP25013 | B14: speaker | C14: local | D14: 2 | F14: =IF(E14="", D14, MIN(D14:E14)) -> 2
A15: CMP27957 | B15: mircophone | C15: local | D15: 3 | E15: 1 | F15: =IF(E15="", D15, MIN(D15:E15)) -> 1
A16: CMP19997 | B16: RAM | C16: local | D16: 2 | F16: =IF(E16="", D16, MIN(D16:E16)) -> 2

Sheet Penalty
A1: customer_desc | B1: Selling_price | C1: Qty_Miss_Penalty | D1: margin
A2: Pixel | B2: 18200 | C2: 0.05 | D2: 0.15
A3: Astro | B3: 18800 | C3: 0.02 | D3: 0.15
A4: Flipsell | B4: 18700 | C4: 0.03 | D4: 0.14
A5: Tosco | B5: 19100 | C5: 0.01 | D5: 0.15

Sheet Sheet1
A1: material | B1: material_desc | C1: 45029 | D1: 45030 | E1: 45031 | F1: 45032 | G1: 45033 | H1: 45034 | I1: 45035 | J1: 45036 | K1: 45037 | L1: 45038 | M1: 45039 | N1: 45040 | O1: 45041 | P1: 45042 | Q1: 45043 | R1: 45044 | S1: 45045 | T1: 45046
A2: CMP15169 | B2: back_cover | C2: 3630 | D2: 3000 | E2: 0 | F2: 0 | G2: 3000 | H2: 3000 | I2: 3000 | J2: 3000 | K2: 3000 | L2: 0 | M2: 0 | N2: 3000 | O2: 3000 | P2: 3000 | Q2: 3000 | R2: 3000 | S2: 0 | T2: 0
A3: CMP12391 | B3: battery | C3: 23410 | D3: 0 | E3: 0 | F3: 0 | G3: 0 | H3: 0 | I3: 0 | J3: 0 | K3: 0 | L3: 0 | M3: 0 | N3: 21000 | O3: 0 | P3: 0 | Q3: 0 | R3: 0 | S3: 0 | T3: 0
A4: CMP19654 | B4: user guide | C4: 7260 | D4: 0 | E4: 0 | F4: 0 | G4: 6000 | H4: 0 | I4: 6000 | J4: 0 | K4: 6000 | L4: 0 | M4: 0 | N4: 0 | O4: 6000 | P4: 0 | Q4: 6000 | R4: 0 | S4: 0 | T4: 0
A5: CMP13058 | B5: charger | C5: 3940 | D5: 3000 | E5: 0 | F5: 0 | G5: 3000 | H5: 3000 | I5: 3000 | J5: 3000 | K5: 3000 | L5: 0 | M5: 0 | N5: 3000 | O5: 3000 | P5: 3000 | Q5: 3000 | R5: 3000 | S5: 0 | T5: 0
A6: CMP13929 | B6: deliverybox | C6: 7260 | D6: 0 | E6: 0 | F6: 0 | G6: 6000 | H6: 0 | I6: 6000 | J6: 0 | K6: 6000 | L6: 0 | M6: 0 | N6: 0 | O6: 6000 | P6: 0 | Q6: 6000 | R6: 0 | S6: 0 | T6: 0
A7: CMP21187 | B7: flash_memory | C7: 37250 | D7: 0 | E7: 0 | F7: 0 | G7: 0 | H7: 0 | I7: 0 | J7: 0 | K7: 0 | L7: 0 | M7: 0 | N7: 0 | O7: 0 | P7: 0 | Q7: 30000 | R7: 0 | S7: 0 | T7: 0
A8: CMP26771 | B8: display_panel | C8: 36300 | D8: 0 | E8: 0 | F8: 0 | G8: 0 | H8: 0 | I8: 0 | J8: 0 | K8: 0 | L8: 0 | M8: 0 | N8: 0 | O8: 0 | P8: 0 | Q8: 30000 | R8: 0 | S8: 0 | T8: 0
A9: CMP23821 | B9: processor | C9: 24450 | D9: 0 | E9: 0 | F9: 0 | G9: 0 | H9: 0 | I9: 0 | J9: 0 | K9: 0 | L9: 0 | M9: 0 | N9: 21000 | O9: 0 | P9: 0 | Q9: 0 | R9: 0 | S9: 0 | T9: 0
A10: CMP28635 | B10: camera_module | C10: 11210 | D10: 0 | E10: 0 | F10: 0 | G10: 0 | H10: 9000 | I10: 0 | J10: 0 | K10: 9000 | L10: 0 | M10: 0 | N10: 0 | O10: 0 | P10: 9000 | Q10: 0 | R10: 0 | S10: 0 | T10: 0
A11: CMP15391 | B11: PCB | C11: 22410 | D11: 0 | E11: 0 | F11: 0 | G11: 0 | H11: 0 | I11: 0 | J11: 0 | K11: 0 | L11: 0 | M11: 0 | N11: 21000 | O11: 0 | P11: 0 | Q11: 0 | R11: 0 | S11: 0 | T11: 0
A12: CMP17473 | B12: power_amplifier | C12: 11000 | D12: 0 | E12: 0 | F12: 0 | G12: 0 | H12: 9000 | I12: 0 | J12: 0 | K12: 9000 | L12: 0 | M12: 0 | N12: 0 | O12: 0 | P12: 9000 | Q12: 0 | R12: 0 | S12: 0 | T12: 0
... A16: CMP19997 | B16: RAM | C16: 7300 | D16: 0 | E16: 0 | F16: 0 | G16: 6000 | H16: 0 | I16: 6000 | J16: 0 | K16: 6000 | L16: 0 | M16: 0 | N16: 0 | O16: 6000 | P16: 0 | Q16: 6000 | R16: 0 | S16: 0 | T16: 0
A18: PRODUCTION PLAN
A20: CMP15169 | B20: back_cover | C20: 3000 | D20: 9000 | E20: 0 | F20: 0 | G20: 5000 | H20: 3000 | I20: 3000 | J20: 3000 | K20: 3000 | L20: 0 | M20: 0 | N20: 3000 | O20: 3000 | P20: 3000 | Q20: 3000 | R20: 3000 | S20: 0 | T20: 0
A21: CMP12391 | B21: battery | C21: 3000 | D21: 9000 | E21: 0 | F21: 0 | G21: 5000 | H21: 3000 | I21: 3000 | J21: 3000 | K21: 3000 | L21: 0 | M21: 0 | N21: 3000 | O21: 3000 | P21: 3000 | Q21: 3000 | R21: 3000 | S21: 0 | T21: 0
A22: CMP19654 | B22: user guide | C22: 3000 | D22: 9000 | E22: 0 | F22: 0 | G22: 5000 | H22: 3000 | I22: 3000 | J22: 3000 | K22: 3000 | L22: 0 | M22: 0 | N22: 3000 | O22: 3000 | P22: 3000 | Q22: 3000 | R22: 3000 | S22: 0 | T22: 0
A23: CMP13058 | B23: charger | C23: 3000 | D23: 9000 | E23: 0 | F23: 0 | G23: 5000 | H23: 3000 | I23: 3000 | J23: 3000 | K23: 3000 | L23: 0 | M23: 0 | N23: 3000 | O23: 3000 | P23: 3000 | Q23: 3000 | R23: 3000 | S23: 0 | T23: 0
A24: CMP13929 | B24: deliverybox | C24: 3000 | D24: 9000 | E24: 0 | F24: 0 | G24: 5000 | H24: 3000 | I24: 3000 | J24: 3000 | K24: 3000 | L24: 0 | M24: 0 | N24: 3000 | O24: 3000 | P24: 3000 | Q24: 3000 | R24: 3000 | S24: 0 | T24: 0
A25: CMP21187 | B25: flash_memory | C25: 3000 | D25: 9000 | E25: 0 | F25: 0 | G25: 5000 | H25: 3000 | I25: 3000 | J25: 3000 | K25: 3000 | L25: 0 | M25: 0 | N25: 3000 | O25: 3000 | P25: 3000 | Q25: 3000 | R25: 3000 | S25: 0 | T25: 0
A26: CMP26771 | B26: display_panel | C26: 3000 | D26: 9000 | E26: 0 | F26: 0 | G26: 5000 | H26: 3000 | I26: 3000 | J26: 3000 | K26: 3000 | L26: 0 | M26: 0 | N26: 3000 | O26: 3000 | P26: 3000 | Q26: 3000 | R26: 3000 | S26: 0 | T26: 0
A27: CMP23821 | B27: processor | C27: 3000 | D27: 9000 | E27: 0 | F27: 0 | G27: 5000 | H27: 3000 | I27: 3000 | J27: 3000 | K27: 3000 | L27: 0 | M27: 0 | N27: 3000 | O27: 3000 | P27: 3000 | Q27: 3000 | R27: 3000 | S27: 0 | T27: 0
A28: CMP28635 | B28: camera_module | C28: 3000 | D28: 9000 | E28: 0 | F28: 0 | G28: 5000 | H28: 3000 | I28: 3000 | J28: 3000 | K28: 3000 | L28: 0 | M28: 0 | N28: 3000 | O28: 3000 | P28: 3000 | Q28: 3000 | R28: 3000 | S28: 0 | T28: 0
A29: CMP15391 | B29: PCB | C29: 3000 | D29: 9000 | E29: 0 | F29: 0 | G29: 5000 | H29: 3000 | I29: 3000 | J29: 3000 | K29: 3000 | L29: 0 | M29: 0 | N29: 3000 | O29: 3000 | P29: 3000 | Q29: 3000 | R29: 3000 | S29: 0 | T29: 0
A30: CMP17473 | B30: power_amplifier | C30: 3000 | D30: 9000 | E30: 0 | F30: 0 | G30: 5000 | H30: 3000 | I30: 3000 | J30: 3000 | K30: 3000 | L30: 0 | M30: 0 | N30: 3000 | O30: 3000 | P30: 3000 | Q30: 3000 | R30: 3000 | S30: 0 | T30: 0
A31: CMP12619 | B31: sensor | C31: 3000 | D31: 9000 | E31: 0 | F31: 0 | G31: 5000 | H31: 3000 | I31: 3000 | J31: 3000 | K31: 3000 | L31: 0 | M31: 0 | N31: 3000 | O31: 3000 | P31: 3000 | Q31: 3000 | R31: 3000 | S31: 0 | T31: 0
... A34: CMP19997 | B34: RAM | C34: 3000 | D34: 9000 | E34: 0 | F34: 0 | G34: 5000 | H34: 3000 | I34: 3000 | J34: 3000 | K34: 3000 | L34: 0 | M34: 0 | N34: 3000 | O34: 3000 | P34: 3000 | Q34: 3000 | R34: 3000 | S34: 0 | T34: 0
A37: MATERIAL REQUIREMENT PLAN
U38: NORMAL LT | V38: EXPRESS LT
A39: CMP15169 | B39: back_cover | C39: =$C2-$C20 -> 630 | D39: =C$39+D$2-D$20 -> -5370 | E39: 0 | F39: 0 | G39: =D$39+G$2-G$20 -> -7370 | H39: =G$39+H$2-H$20 -> -7370 | I39: =H$39+I$2-I$20 -> -7370 | J39: =I$39+J$2-J$20 -> -7370 | K39: =J$39+K$2-K$20 -> -7370 | L39: 0 | M39: 0 | N39: =K$39+N$2-N$20 -> -7370 | O39: =N$39+O$2-O$20 -> -7370 | P39: =O$39+P$2-P$20 -> -7370 | Q39: =P$39+Q$2-Q$20 -> -7370 | R39: =Q$39+R$2-R$20 -> -7370 | S39: 0 | T39: 0 | U39: 1
A40: CMP12391 | B40: battery | C40: =$C3-$C21 -> 20410 | D40: =$C40+$D3-$D21 -> 11410 | E40: 0 | F40: 0 | G40: =$D40+$G3-$G21 -> 6410 | H40: =$G40+$H3-$H21 -> 3410 | I40: =$H40+$I3-$I21 -> 410 | J40: =$I40+$J3-$J21 -> -2590 | K40: =$J40+$K3-$K21 -> -5590 | L40: 0 | M40: 0 | N40: =$K40+N3-N21 -> 12410 | O40: =$N40+$O3-$O21 -> 9410 | P40: =$O40+$P3-$P21 -> 6410 | Q40: =$P40+$Q3-$Q21 -> 3410 | R40: =$Q40+$R3-$R21 -> 410 | S40: 0 | T40: 0 | U40: 7 | V40: 3
A41: CMP19654 | B41: user guide | C41: =$C4-$C22 -> 4260 | D41: =$C41+$D4-$D22 -> -4740 | E41: 0 | F41: 0 | G41: =$D41+$G4-$G22 -> -3740 | H41: =$G41+$H4-$H22 -> -6740 | I41: =$H41+$I4-$I22 -> -3740 | J41: =$I41+$J4-$J22 -> -6740 | K41: =$J41+$K4-$K22 -> -3740 | L41: 0 | M41: 0 | N41: =$K41+N4-N22 -> -6740 | O41: =$N41+$O4-$O22 -> -3740 | P41: =$O41+$P4-$P22 -> -6740 | Q41: =$P41+$Q4-$Q22 -> -3740 | R41: =$Q41+$R4-$R22 -> -6740 | S41: 0 | T41: 0 | U41: 2
A42: CMP13058 | B42: charger | C42: =$C5-$C23 -> 940 | D42: =$C42+$D5-$D23 -> -5060 | E42: 0 | F42: 0 | G42: =$D42+$G5-$G23 -> -7060 | H42: =$G42+$H5-$H23 -> -7060 | I42: =$H42+$I5-$I23 -> -7060 | J42: =$I42+$J5-$J23 -> -7060 | K42: =$J42+$K5-$K23 -> -7060 | L42: 0 | M42: 0 | N42: =$K42+N5-N23 -> -7060 | O42: =$N42+$O5-$O23 -> -7060 | P42: =$O42+$P5-$P23 -> -7060 | Q42: =$P42+$Q5-$Q23 -> -7060 | R42: =$Q42+$R5-$R23 -> -7060 | S42: 0 | T42: 0 | U42: 1
A43: CMP13929 | B43: deliverybox | C43: =$C6-$C24 -> 4260 | D43: =$C43+$D6-$D24 -> -4740 | E43: 0 | F43: 0 | G43: =$D43+$G6-$G24 -> -3740 | H43: =$G43+$H6-$H24 -> -6740 | I43: =$H43+$I6-$I24 -> -3740 | J43: =$I43+$J6-$J24 -> -6740 | K43: =$J43+$K6-$K24 -> -3740 | L43: 0 | M43: 0 | N43: =$K43+N6-N24 -> -6740 | O43: =$N43+$O6-$O24 -> -3740 | P43: =$O43+$P6-$P24 -> -6740 | Q43: =$P43+$Q6-$Q24 -> -3740 | R43: =$Q43+$R6-$R24 -> -6740 | S43: 0 | T43: 0 | U43: 2
A44: CMP21187 | B44: flash_memory | C44: =$C7-$C25 -> 34250 | D44: =$C44+$D7-$D25 -> 25250 | E44: 0 | F44: 0 | G44: =$D44+$G7-$G25 -> 20250 | H44: =$G44+$H7-$H25 -> 17250 | I44: =$H44+$I7-$I25 -> 14250 | J44: =$I44+$J7-$J25 -> 11250 | K44: =$J44+$K7-$K25 -> 8250 | L44: 0 | M44: 0 | N44: =$K44+N7-N25 -> 5250 | O44: =$N44+$O7-$O25 -> 2250 | P44: =$O44+$P7-$P25 -> -750 | Q44: =$P44+$Q7-$Q25 -> 26250 | R44: =$Q44+$R7-$R25 -> 23250 | S44: 0 | T44: 0 | U44: 10 | V44: 3
A45: CMP26771 | B45: display_panel | C45: =$C8-$C26 -> 33300 | D45: =$C45+$D8-$D26 -> 24300 | E45: 0 | F45: 0 | G45: =$D45+$G8-$G26 -> 19300 | H45: =$G45+$H8-$H26 -> 16300 | I45: =$H45+$I8-$I26 -> 13300 | J45: =$I45+$J8-$J26 -> 10300 | K45: =$J45+$K8-$K26 -> 7300 | L45: 0 | M45: 0 | N45: =$K45+N8-N26 -> 4300 | O45: =$N45+$O8-$O26 -> 1300 | P45: =$O45+$P8-$P26 -> -1700 | Q45: =$P45+$Q8-$Q26 -> 25300 | R45: =$Q45+$R8-$R26 -> 22300 | S45: 0 | T45: 0 | U45: 10 | V45: 3
A46: CMP23821 | B46: processor | C46: =$C9-$C27 -> 21450 | D46: =$C46+$D9-$D27 -> 12450 | E46: 0 | F46: 0 | G46: =$D46+$G9-$G27 -> 7450 | H46: =$G46+$H9-$H27 -> 4450 | I46: =$H46+$I9-$I27 -> 1450 | J46: =$I46+$J9-$J27 -> -1550 | K46: =$J46+$K9-$K27 -> -4550 | L46: 0 | M46: 0 | N46: =$K46+N9-N27 -> 13450 | O46: =$N46+$O9-$O27 -> 10450 | P46: =$O46+$P9-$P27 -> 7450 | Q46: =$P46+$Q9-$Q27 -> 4450 | R46: =$Q46+$R9-$R27 -> 1450 | S46: 0 | T46: 0 | U46: 7 | V46: 3
A47: CMP28635 | B47: camera_module | C47: =$C10-$C28 -> 8210 | D47: =$C47+$D10-$D28 -> -790 | E47: 0 | F47: 0 | G47: =$D47+$G10-$G28 -> -5790 | H47: =$G47+$H10-$H28 -> 210 | I47: =$H47+$I10-$I28 -> -2790 | J47: =$I47+$J10-$J28 -> -5790 | K47: =$J47+$K10-$K28 -> 210 | L47: 0 | M47: 0 | N47: =$K47+N10-N28 -> -2790 | O47: =$N47+$O10-$O28 -> -5790 | P47: =$O47+$P10-$P28 -> 210 | Q47: =$P47+$Q10-$Q28 -> -2790 | R47: =$Q47+$R10-$R28 -> -5790 | S47: 0 | T47: 0 | U47: 3
A48: CMP15391 | B48: PCB | C48: =$C11-$C29 -> 19410 | D48: =$C48+$D11-$D29 -> 10410 | E48: 0 | F48: 0 | G48: =$D48+$G11-$G29 -> 5410 | H48: =$G48+$H11-$H29 -> 2410 | I48: =$H48+$I11-$I29 -> -590 | J48: =$I48+$J11-$J29 -> -3590 | K48: =$J48+$K11-$K29 -> -6590 | L48: 0 | M48: 0 | N48: =$K48+N11-N29 -> 11410 | O48: =$N48+$O11-$O29 -> 8410 | P48: =$O48+$P11-$P29 -> 5410 | Q48: =$P48+$Q11-$Q29 -> 2410 | R48: =$Q48+$R11-$R29 -> -590 | S48: 0 | T48: 0 | U48: 7 | V48: 3
A49: CMP17473 | B49: power_amplifier | C49: =$C12-$C30 -> 8000 | D49: =$C49+$D12-$D30 -> -1000 | E49: 0 | F49: 0 | G49: =$D49+$G12-$G30 -> -6000 | H49: =$G49+$H12-$H30 -> 0 | I49: =$H49+$I12-$I30 -> -3000 | J49: =$I49+$J12-$J30 -> -6000 | K49: =$J49+$K12-$K30 -> 0 | L49: 0 | M49: 0 | N49: =$K49+N12-N30 -> -3000 | O49: =$N49+$O12-$O30 -> -6000 | P49: =$O49+$P12-$P30 -> 0 | Q49: =$P49+$Q12-$Q30 -> -3000 | R49: =$Q49+$R12-$R30 -> -6000 | S49: 0 | T49: 0 | U49: 3 | V49: 1
...

Sheet Sheet2
A1: material | B1: material_desc | C1: 45029 | D1: 45030 | E1: 45031 | F1: 45032 | G1: 45033 | H1: 45034 | I1: 45035 | J1: 45036 | K1: 45037 | L1: 45038 | M1: 45039 | N1: 45040 | O1: 45041 | P1: 45042 | Q1: 45043 | R1: 45044 | S1: 45045 | T1: 45046 | U1: NORMAL LT | V1: EXPRESS LT
A2: CMP15169 | B2: back_cover | C2: =Sheet1!C39 -> 630 | D2: =Sheet1!D39 -> -5370 | E2: =Sheet1!E39 -> 0 | F2: =Sheet1!F39 -> 0 | G2: =Sheet1!G39 -> -7370 | H2: =Sheet1!H39 -> -7370 | I2: =Sheet1!I39 -> -7370 | J2: =Sheet1!J39 -> -7370 | ... V2: =Sheet1!V39 -> 0
A3: CMP12391 | B3: battery | C3: =Sheet1!C40 -> 20410 | D3: =Sheet1!D40 -> 11410 | E3: =Sheet1!E40 -> 0 | F3: =Sheet1!F40 -> 0 | G3: =Sheet1!G40 -> 6410 | H3: =Sheet1!H40 -> 3410 | I3: =Sheet1!I40 -> 410 | J3: =Sheet1!J40 -> -2590 | ... V3: =Sheet1!V40 -> 3
A4: CMP19654 | B4: user guide | C4: =Sheet1!C41 -> 4260 | D4: =Sheet1!D41 -> -4740 | E4: =Sheet1!E41 -> 0 | F4: =Sheet1!F41 -> 0 | G4: =Sheet1!G41 -> -3740 | H4: =Sheet1!H41 -> -6740 | I4: =Sheet1!I41 -> -3740 | J4: =Sheet1!J41 -> -6740 | ... V4: =Sheet1!V41 -> 0
A5: CMP13058 | B5: charger | C5: =Sheet1!C42 -> 940 | D5: =Sheet1!D42 -> -5060 | E5: =Sheet1!E42 -> 0 | F5: =Sheet1!F42 -> 0 | G5: =Sheet1!G42 -> -7060 | H5: =Sheet1!H42 -> -7060 | I5: =Sheet1!I42 -> -7060 | J5: =Sheet1!J42 -> -7060 | ... V5: =Sheet1!V42 -> 0
A6: CMP13929 | B6: deliverybox | C6: =Sheet1!C43 -> 4260 | D6: =Sheet1!D43 -> -4740 | E6: =Sheet1!E43 -> 0 | F6: =Sheet1!F43 -> 0 | G6: =Sheet1!G43 -> -3740 | H6: =Sheet1!H43 -> -6740 | I6: =Sheet1!I43 -> -3740 | J6: =Sheet1!J43 -> -6740 | ... V6: =Sheet1!V43 -> 0
A7: CMP21187 | B7: flash_memory | C7: =Sheet1!C44 -> 34250 | D7: =Sheet1!D44 -> 25250 | E7: =Sheet1!E44 -> 0 | F7: =Sheet1!F44 -> 0 | G7: =Sheet1!G44 -> 20250 | H7: =Sheet1!H44 -> 17250 | I7: =Sheet1!I44 -> 14250 | J7: =Sheet1!J44 -> 11250 | ... V7: =Sheet1!V44 -> 3
A8: CMP26771 | B8: display_panel | C8: =Sheet1!C45 -> 33300 | D8: =Sheet1!D45 -> 24300 | E8: =Sheet1!E45 -> 0 | F8: =Sheet1!F45 -> 0 | G8: =Sheet1!G45 -> 19300 | H8: =Sheet1!H45 -> 16300 | I8: =Sheet1!I45 -> 13300 | J8: =Sheet1!J45 -> 10300 | ... V8: =Sheet1!V45 -> 3
A9: CMP23821 | B9: processor | C9: =Sheet1!C46 -> 21450 | D9: =Sheet1!D46 -> 12450 | E9: =Sheet1!E46 -> 0 | F9: =Sheet1!F46 -> 0 | G9: =Sheet1!G46 -> 7450 | H9: =Sheet1!H46 -> 4450 | I9: =Sheet1!I46 -> 1450 | J9: =Sheet1!J46 -> -1550 | ... V9: =Sheet1!V46 -> 3
A10: CMP28635 | B10: camera_module | C10: =Sheet1!C47 -> 8210 | D10: =Sheet1!D47 -> -790 | E10: =Sheet1!E47 -> 0 | F10: =Sheet1!F47 -> 0 | G10: =Sheet1!G47 -> -5790 | H10: =Sheet1!H47 -> 210 | I10: =Sheet1!I47 -> -2790 | J10: =Sheet1!J47 -> -5790 | ... V10: =Sheet1!V47 -> 0
A11: CMP15391 | B11: PCB | C11: =Sheet1!C48 -> 19410 | D11: =Sheet1!D48 -> 10410 | E11: =Sheet1!E48 -> 0 | F11: =Sheet1!F48 -> 0 | G11: =Sheet1!G48 -> 5410 | H11: =Sheet1!H48 -> 2410 | I11: =Sheet1!I48 -> -590 | J11: =Sheet1!J48 -> -3590 | ... V11: =Sheet1!V48 -> 3
A12: CMP17473 | B12: power_amplifier | C12: =Sheet1!C49 -> 8000 | D12: =Sheet1!D49 -> -1000 | E12: =Sheet1!E49 -> 0 | F12: =Sheet1!F49 -> 0 | G12: =Sheet1!G49 -> -6000 | H12: =Sheet1!H49 -> 0 | I12: =Sheet1!I49 -> -3000 | J12: =Sheet1!J49 -> -6000 | ... V12: =Sheet1!V49 -> 1
A13: CMP12619 | B13: sensor | C13: =Sheet1!C50 -> 4840 | D13: =Sheet1!D50 -> -4160 | E13: =Sheet1!E50 -> 0 | F13: =Sheet1!F50 -> 0 | G13: =Sheet1!G50 -> -3160 | H13: =Sheet1!H50 -> -6160 | I13: =Sheet1!I50 -> -3160 | J13: =Sheet1!J50 -> -6160 | ... V13: =Sheet1!V50 -> 0
... A16: CMP19997 | B16: RAM | C16: =Sheet1!C53 -> 4300 | D16: =Sheet1!D53 -> -4700 | E16: =Sheet1!E53 -> 0 | F16: =Sheet1!F53 -> 0 | G16: =Sheet1!G53 -> -3700 | H16: =Sheet1!H53 -> -6700 | I16: =Sheet1!I53 -> -3700 | J16: =Sheet1!J53 -> -6700 | ... V16: =Sheet1!V53 -> 0
